[2024-06-28T11:54:01.190+0000] {local_task_job_runner.py:120} INFO - ::group::Pre task execution logs
[2024-06-28T11:54:01.211+0000] {taskinstance.py:2076} INFO - Dependencies all met for dep_context=non-requeueable deps ti=<TaskInstance: make_predictions.make_predictions_task manual__2024-06-28T11:53:57.518141+00:00 [queued]>
[2024-06-28T11:54:01.216+0000] {taskinstance.py:2076} INFO - Dependencies all met for dep_context=requeueable deps ti=<TaskInstance: make_predictions.make_predictions_task manual__2024-06-28T11:53:57.518141+00:00 [queued]>
[2024-06-28T11:54:01.217+0000] {taskinstance.py:2306} INFO - Starting attempt 1 of 2
[2024-06-28T11:54:01.228+0000] {taskinstance.py:2330} INFO - Executing <Task(PythonOperator): make_predictions_task> on 2024-06-28 11:53:57.518141+00:00
[2024-06-28T11:54:01.249+0000] {warnings.py:112} WARNING - /home/***/.local/lib/python3.12/site-packages/***/task/task_runner/standard_task_runner.py:61: DeprecationWarning: This process (pid=43) is multi-threaded, use of fork() may lead to deadlocks in the child.
  pid = os.fork()

[2024-06-28T11:54:01.252+0000] {standard_task_runner.py:63} INFO - Started process 49 to run task
[2024-06-28T11:54:01.251+0000] {standard_task_runner.py:90} INFO - Running: ['***', 'tasks', 'run', 'make_predictions', 'make_predictions_task', 'manual__2024-06-28T11:53:57.518141+00:00', '--job-id', '51', '--raw', '--subdir', 'DAGS_FOLDER/make_predictions.py', '--cfg-path', '/tmp/tmpewsy7tjf']
[2024-06-28T11:54:01.257+0000] {standard_task_runner.py:91} INFO - Job 51: Subtask make_predictions_task
[2024-06-28T11:54:01.273+0000] {warnings.py:112} WARNING - /home/***/.local/lib/python3.12/site-packages/***/settings.py:195: DeprecationWarning: The sql_alchemy_conn option in [core] has been moved to the sql_alchemy_conn option in [database] - the old setting has been used, but please update your config.
  SQL_ALCHEMY_CONN = conf.get("database", "SQL_ALCHEMY_CONN")

[2024-06-28T11:54:01.302+0000] {task_command.py:426} INFO - Running <TaskInstance: make_predictions.make_predictions_task manual__2024-06-28T11:53:57.518141+00:00 [running]> on host eb8c7fbba7b2
[2024-06-28T11:54:01.359+0000] {taskinstance.py:2648} INFO - Exporting env vars: AIRFLOW_CTX_DAG_OWNER='***' AIRFLOW_CTX_DAG_ID='make_predictions' AIRFLOW_CTX_TASK_ID='make_predictions_task' AIRFLOW_CTX_EXECUTION_DATE='2024-06-28T11:53:57.518141+00:00' AIRFLOW_CTX_TRY_NUMBER='1' AIRFLOW_CTX_DAG_RUN_ID='manual__2024-06-28T11:53:57.518141+00:00'
[2024-06-28T11:54:01.360+0000] {taskinstance.py:430} INFO - ::endgroup::
[2024-06-28T11:54:01.371+0000] {make_predictions.py:42} INFO - Loading model from /opt/***/models/stock_model.keras
[2024-06-28T11:54:01.533+0000] {make_predictions.py:44} INFO - Model loaded from /opt/***/models/stock_model.keras
[2024-06-28T11:54:01.542+0000] {taskinstance.py:441} INFO - ::group::Post task execution logs
[2024-06-28T11:54:01.542+0000] {taskinstance.py:2905} ERROR - Task failed with exception
Traceback (most recent call last):
  File "/home/airflow/.local/lib/python3.12/site-packages/airflow/models/taskinstance.py", line 465, in _execute_task
    result = _execute_callable(context=context, **execute_callable_kwargs)
             ^^^^^^^^^^^^^^^^^^^^^^^^^^^^^^^^^^^^^^^^^^^^^^^^^^^^^^^^^^^^^
  File "/home/airflow/.local/lib/python3.12/site-packages/airflow/models/taskinstance.py", line 432, in _execute_callable
    return execute_callable(context=context, **execute_callable_kwargs)
           ^^^^^^^^^^^^^^^^^^^^^^^^^^^^^^^^^^^^^^^^^^^^^^^^^^^^^^^^^^^^
  File "/home/airflow/.local/lib/python3.12/site-packages/airflow/models/baseoperator.py", line 401, in wrapper
    return func(self, *args, **kwargs)
           ^^^^^^^^^^^^^^^^^^^^^^^^^^^
  File "/home/airflow/.local/lib/python3.12/site-packages/airflow/operators/python.py", line 235, in execute
    return_value = self.execute_callable()
                   ^^^^^^^^^^^^^^^^^^^^^^^
  File "/home/airflow/.local/lib/python3.12/site-packages/airflow/operators/python.py", line 252, in execute_callable
    return self.python_callable(*self.op_args, **self.op_kwargs)
           ^^^^^^^^^^^^^^^^^^^^^^^^^^^^^^^^^^^^^^^^^^^^^^^^^^^^^
  File "/opt/airflow/dags/make_predictions.py", line 53, in make_predictions
    output_predict[:len(data)] = data
    ~~~~~~~~~~~~~~^^^^^^^^^^^^
ValueError: could not convert string to float: '2023-06-28'
[2024-06-28T11:54:01.553+0000] {taskinstance.py:1206} INFO - Marking task as UP_FOR_RETRY. dag_id=make_predictions, task_id=make_predictions_task, run_id=manual__2024-06-28T11:53:57.518141+00:00, execution_date=20240628T115357, start_date=20240628T115401, end_date=20240628T115401
[2024-06-28T11:54:01.560+0000] {standard_task_runner.py:110} ERROR - Failed to execute job 51 for task make_predictions_task (could not convert string to float: '2023-06-28'; 49)
[2024-06-28T11:54:01.591+0000] {local_task_job_runner.py:240} INFO - Task exited with return code 1
[2024-06-28T11:54:01.602+0000] {taskinstance.py:3503} INFO - 0 downstream tasks scheduled from follow-on schedule check
[2024-06-28T11:54:01.603+0000] {local_task_job_runner.py:222} INFO - ::endgroup::
