[2024-06-27T18:00:54.743+0000] {local_task_job_runner.py:120} INFO - ::group::Pre task execution logs
[2024-06-27T18:00:54.781+0000] {taskinstance.py:2076} INFO - Dependencies all met for dep_context=non-requeueable deps ti=<TaskInstance: train_model.train_stock_model manual__2024-06-27T18:00:49.196743+00:00 [queued]>
[2024-06-27T18:00:54.790+0000] {taskinstance.py:2076} INFO - Dependencies all met for dep_context=requeueable deps ti=<TaskInstance: train_model.train_stock_model manual__2024-06-27T18:00:49.196743+00:00 [queued]>
[2024-06-27T18:00:54.790+0000] {taskinstance.py:2306} INFO - Starting attempt 1 of 2
[2024-06-27T18:00:54.803+0000] {taskinstance.py:2330} INFO - Executing <Task(PythonOperator): train_stock_model> on 2024-06-27 18:00:49.196743+00:00
[2024-06-27T18:00:54.812+0000] {warnings.py:112} WARNING - /home/***/.local/lib/python3.12/site-packages/***/task/task_runner/standard_task_runner.py:61: DeprecationWarning: This process (pid=44) is multi-threaded, use of fork() may lead to deadlocks in the child.
  pid = os.fork()

[2024-06-27T18:00:54.813+0000] {standard_task_runner.py:63} INFO - Started process 49 to run task
[2024-06-27T18:00:54.815+0000] {standard_task_runner.py:90} INFO - Running: ['***', 'tasks', 'run', 'train_model', 'train_stock_model', 'manual__2024-06-27T18:00:49.196743+00:00', '--job-id', '233', '--raw', '--subdir', 'DAGS_FOLDER/train_model.py', '--cfg-path', '/tmp/tmpe__t4cmk']
[2024-06-27T18:00:54.817+0000] {standard_task_runner.py:91} INFO - Job 233: Subtask train_stock_model
[2024-06-27T18:00:54.831+0000] {warnings.py:112} WARNING - /home/***/.local/lib/python3.12/site-packages/***/settings.py:195: DeprecationWarning: The sql_alchemy_conn option in [core] has been moved to the sql_alchemy_conn option in [database] - the old setting has been used, but please update your config.
  SQL_ALCHEMY_CONN = conf.get("database", "SQL_ALCHEMY_CONN")

[2024-06-27T18:00:54.859+0000] {task_command.py:426} INFO - Running <TaskInstance: train_model.train_stock_model manual__2024-06-27T18:00:49.196743+00:00 [running]> on host 5daea60ed64a
[2024-06-27T18:00:54.913+0000] {taskinstance.py:2648} INFO - Exporting env vars: AIRFLOW_CTX_DAG_OWNER='***' AIRFLOW_CTX_DAG_ID='train_model' AIRFLOW_CTX_TASK_ID='train_stock_model' AIRFLOW_CTX_EXECUTION_DATE='2024-06-27T18:00:49.196743+00:00' AIRFLOW_CTX_TRY_NUMBER='1' AIRFLOW_CTX_DAG_RUN_ID='manual__2024-06-27T18:00:49.196743+00:00'
[2024-06-27T18:00:54.914+0000] {taskinstance.py:430} INFO - ::endgroup::
[2024-06-27T18:00:54.953+0000] {taskinstance.py:441} INFO - ::group::Post task execution logs
[2024-06-27T18:00:54.953+0000] {taskinstance.py:2905} ERROR - Task failed with exception
Traceback (most recent call last):
  File "/home/airflow/.local/lib/python3.12/site-packages/airflow/models/taskinstance.py", line 465, in _execute_task
    result = _execute_callable(context=context, **execute_callable_kwargs)
             ^^^^^^^^^^^^^^^^^^^^^^^^^^^^^^^^^^^^^^^^^^^^^^^^^^^^^^^^^^^^^
  File "/home/airflow/.local/lib/python3.12/site-packages/airflow/models/taskinstance.py", line 432, in _execute_callable
    return execute_callable(context=context, **execute_callable_kwargs)
           ^^^^^^^^^^^^^^^^^^^^^^^^^^^^^^^^^^^^^^^^^^^^^^^^^^^^^^^^^^^^
  File "/home/airflow/.local/lib/python3.12/site-packages/airflow/models/baseoperator.py", line 401, in wrapper
    return func(self, *args, **kwargs)
           ^^^^^^^^^^^^^^^^^^^^^^^^^^^
  File "/home/airflow/.local/lib/python3.12/site-packages/airflow/operators/python.py", line 235, in execute
    return_value = self.execute_callable()
                   ^^^^^^^^^^^^^^^^^^^^^^^
  File "/home/airflow/.local/lib/python3.12/site-packages/airflow/operators/python.py", line 252, in execute_callable
    return self.python_callable(*self.op_args, **self.op_kwargs)
           ^^^^^^^^^^^^^^^^^^^^^^^^^^^^^^^^^^^^^^^^^^^^^^^^^^^^^
  File "/opt/airflow/dags/train_model.py", line 56, in train_model
    modelnn = Model(learning_rate, num_layers, df_train.shape[1], size_layer, df_train.shape[1], dropout_rate)
              ^^^^^^^^^^^^^^^^^^^^^^^^^^^^^^^^^^^^^^^^^^^^^^^^^^^^^^^^^^^^^^^^^^^^^^^^^^^^^^^^^^^^^^^^^^^^^^^^
  File "/opt/airflow/dags/train_model.py", line 32, in __init__
    rnn_cells = tf.compat.v1.nn.rnn_cell.MultiRNNCell(
                ^^^^^^^^^^^^^^^^^^^^^^^^^^^^^^^^^^^^^
  File "/home/airflow/.local/lib/python3.12/site-packages/tensorflow/python/util/lazy_loader.py", line 207, in __getattr__
    raise AttributeError(
AttributeError: `MultiRNNCell` is not available with Keras 3.
[2024-06-27T18:00:54.984+0000] {taskinstance.py:1206} INFO - Marking task as UP_FOR_RETRY. dag_id=train_model, task_id=train_stock_model, run_id=manual__2024-06-27T18:00:49.196743+00:00, execution_date=20240627T180049, start_date=20240627T180054, end_date=20240627T180054
[2024-06-27T18:00:54.992+0000] {standard_task_runner.py:110} ERROR - Failed to execute job 233 for task train_stock_model (`MultiRNNCell` is not available with Keras 3.; 49)
[2024-06-27T18:00:55.029+0000] {local_task_job_runner.py:240} INFO - Task exited with return code 1
[2024-06-27T18:00:55.040+0000] {taskinstance.py:3503} INFO - 0 downstream tasks scheduled from follow-on schedule check
[2024-06-27T18:00:55.041+0000] {local_task_job_runner.py:222} INFO - ::endgroup::
