[2024-06-27T18:06:01.419+0000] {local_task_job_runner.py:120} INFO - ::group::Pre task execution logs
[2024-06-27T18:06:01.442+0000] {taskinstance.py:2076} INFO - Dependencies all met for dep_context=non-requeueable deps ti=<TaskInstance: train_model.train_stock_model manual__2024-06-27T18:05:57.761560+00:00 [queued]>
[2024-06-27T18:06:01.447+0000] {taskinstance.py:2076} INFO - Dependencies all met for dep_context=requeueable deps ti=<TaskInstance: train_model.train_stock_model manual__2024-06-27T18:05:57.761560+00:00 [queued]>
[2024-06-27T18:06:01.447+0000] {taskinstance.py:2306} INFO - Starting attempt 1 of 2
[2024-06-27T18:06:01.455+0000] {taskinstance.py:2330} INFO - Executing <Task(PythonOperator): train_stock_model> on 2024-06-27 18:05:57.761560+00:00
[2024-06-27T18:06:01.467+0000] {warnings.py:112} WARNING - /home/***/.local/lib/python3.12/site-packages/***/task/task_runner/standard_task_runner.py:61: DeprecationWarning: This process (pid=44) is multi-threaded, use of fork() may lead to deadlocks in the child.
  pid = os.fork()

[2024-06-27T18:06:01.469+0000] {standard_task_runner.py:63} INFO - Started process 49 to run task
[2024-06-27T18:06:01.470+0000] {standard_task_runner.py:90} INFO - Running: ['***', 'tasks', 'run', 'train_model', 'train_stock_model', 'manual__2024-06-27T18:05:57.761560+00:00', '--job-id', '266', '--raw', '--subdir', 'DAGS_FOLDER/train_model.py', '--cfg-path', '/tmp/tmpezqiq5ch']
[2024-06-27T18:06:01.472+0000] {standard_task_runner.py:91} INFO - Job 266: Subtask train_stock_model
[2024-06-27T18:06:01.525+0000] {warnings.py:112} WARNING - /home/***/.local/lib/python3.12/site-packages/***/settings.py:195: DeprecationWarning: The sql_alchemy_conn option in [core] has been moved to the sql_alchemy_conn option in [database] - the old setting has been used, but please update your config.
  SQL_ALCHEMY_CONN = conf.get("database", "SQL_ALCHEMY_CONN")

[2024-06-27T18:06:01.561+0000] {task_command.py:426} INFO - Running <TaskInstance: train_model.train_stock_model manual__2024-06-27T18:05:57.761560+00:00 [running]> on host 5daea60ed64a
[2024-06-27T18:06:01.670+0000] {taskinstance.py:2648} INFO - Exporting env vars: AIRFLOW_CTX_DAG_OWNER='***' AIRFLOW_CTX_DAG_ID='train_model' AIRFLOW_CTX_TASK_ID='train_stock_model' AIRFLOW_CTX_EXECUTION_DATE='2024-06-27T18:05:57.761560+00:00' AIRFLOW_CTX_TRY_NUMBER='1' AIRFLOW_CTX_DAG_RUN_ID='manual__2024-06-27T18:05:57.761560+00:00'
[2024-06-27T18:06:01.671+0000] {taskinstance.py:430} INFO - ::endgroup::
[2024-06-27T18:06:01.894+0000] {logging_mixin.py:188} WARNING - train loop:   0%|          | 0/300 [00:00<?, ?it/s]
[2024-06-27T18:06:01.906+0000] {logging_mixin.py:188} WARNING - train loop:   0%|          | 0/300 [00:00<?, ?it/s]
[2024-06-27T18:06:01.906+0000] {taskinstance.py:441} INFO - ::group::Post task execution logs
[2024-06-27T18:06:01.907+0000] {taskinstance.py:2905} ERROR - Task failed with exception
Traceback (most recent call last):
  File "/home/airflow/.local/lib/python3.12/site-packages/airflow/models/taskinstance.py", line 465, in _execute_task
    result = _execute_callable(context=context, **execute_callable_kwargs)
             ^^^^^^^^^^^^^^^^^^^^^^^^^^^^^^^^^^^^^^^^^^^^^^^^^^^^^^^^^^^^^
  File "/home/airflow/.local/lib/python3.12/site-packages/airflow/models/taskinstance.py", line 432, in _execute_callable
    return execute_callable(context=context, **execute_callable_kwargs)
           ^^^^^^^^^^^^^^^^^^^^^^^^^^^^^^^^^^^^^^^^^^^^^^^^^^^^^^^^^^^^
  File "/home/airflow/.local/lib/python3.12/site-packages/airflow/models/baseoperator.py", line 401, in wrapper
    return func(self, *args, **kwargs)
           ^^^^^^^^^^^^^^^^^^^^^^^^^^^
  File "/home/airflow/.local/lib/python3.12/site-packages/airflow/operators/python.py", line 235, in execute
    return_value = self.execute_callable()
                   ^^^^^^^^^^^^^^^^^^^^^^^
  File "/home/airflow/.local/lib/python3.12/site-packages/airflow/operators/python.py", line 252, in execute_callable
    return self.python_callable(*self.op_args, **self.op_kwargs)
           ^^^^^^^^^^^^^^^^^^^^^^^^^^^^^^^^^^^^^^^^^^^^^^^^^^^^^
  File "/opt/airflow/dags/train_model.py", line 66, in train_model
    logits, *last_states = modelnn.model([batch_x] + init_states)
                           ^^^^^^^^^^^^^^^^^^^^^^^^^^^^^^^^^^^^^^
  File "/home/airflow/.local/lib/python3.12/site-packages/keras/src/utils/traceback_utils.py", line 122, in error_handler
    raise e.with_traceback(filtered_tb) from None
  File "/home/airflow/.local/lib/python3.12/site-packages/keras/src/layers/rnn/lstm.py", line 229, in call
    c_tm1 = states[1]  # previous carry state
            ~~~~~~^^^
IndexError: Exception encountered when calling LSTMCell.call().

[1mlist index out of range[0m

Arguments received by LSTMCell.call():
  â€¢ inputs=tf.Tensor(shape=(1, 1), dtype=float32)
  â€¢ states=['tf.Tensor(shape=(1, 128), dtype=float32)']
  â€¢ training=False
[2024-06-27T18:06:01.931+0000] {taskinstance.py:1206} INFO - Marking task as UP_FOR_RETRY. dag_id=train_model, task_id=train_stock_model, run_id=manual__2024-06-27T18:05:57.761560+00:00, execution_date=20240627T180557, start_date=20240627T180601, end_date=20240627T180601
[2024-06-27T18:06:01.956+0000] {standard_task_runner.py:110} ERROR - Failed to execute job 266 for task train_stock_model (Exception encountered when calling LSTMCell.call().

[1mlist index out of range[0m

Arguments received by LSTMCell.call():
  â€¢ inputs=tf.Tensor(shape=(1, 1), dtype=float32)
  â€¢ states=['tf.Tensor(shape=(1, 128), dtype=float32)']
  â€¢ training=False; 49)
[2024-06-27T18:06:02.010+0000] {local_task_job_runner.py:240} INFO - Task exited with return code 1
[2024-06-27T18:06:02.031+0000] {taskinstance.py:3503} INFO - 0 downstream tasks scheduled from follow-on schedule check
[2024-06-27T18:06:02.033+0000] {local_task_job_runner.py:222} INFO - ::endgroup::
