[2024-06-27T19:10:34.438+0000] {local_task_job_runner.py:120} INFO - ::group::Pre task execution logs
[2024-06-27T19:10:34.458+0000] {taskinstance.py:2076} INFO - Dependencies all met for dep_context=non-requeueable deps ti=<TaskInstance: make_predictions.make_predictions_task manual__2024-06-27T19:10:30.429657+00:00 [queued]>
[2024-06-27T19:10:34.471+0000] {taskinstance.py:2076} INFO - Dependencies all met for dep_context=requeueable deps ti=<TaskInstance: make_predictions.make_predictions_task manual__2024-06-27T19:10:30.429657+00:00 [queued]>
[2024-06-27T19:10:34.472+0000] {taskinstance.py:2306} INFO - Starting attempt 1 of 2
[2024-06-27T19:10:34.489+0000] {taskinstance.py:2330} INFO - Executing <Task(PythonOperator): make_predictions_task> on 2024-06-27 19:10:30.429657+00:00
[2024-06-27T19:10:34.520+0000] {warnings.py:112} WARNING - /home/***/.local/lib/python3.12/site-packages/***/task/task_runner/standard_task_runner.py:61: DeprecationWarning: This process (pid=2461) is multi-threaded, use of fork() may lead to deadlocks in the child.
  pid = os.fork()

[2024-06-27T19:10:34.522+0000] {standard_task_runner.py:63} INFO - Started process 2467 to run task
[2024-06-27T19:10:34.524+0000] {standard_task_runner.py:90} INFO - Running: ['***', 'tasks', 'run', 'make_predictions', 'make_predictions_task', 'manual__2024-06-27T19:10:30.429657+00:00', '--job-id', '863', '--raw', '--subdir', 'DAGS_FOLDER/make_predictions.py', '--cfg-path', '/tmp/tmpkpcouwa4']
[2024-06-27T19:10:34.529+0000] {standard_task_runner.py:91} INFO - Job 863: Subtask make_predictions_task
[2024-06-27T19:10:34.543+0000] {warnings.py:112} WARNING - /home/***/.local/lib/python3.12/site-packages/***/settings.py:195: DeprecationWarning: The sql_alchemy_conn option in [core] has been moved to the sql_alchemy_conn option in [database] - the old setting has been used, but please update your config.
  SQL_ALCHEMY_CONN = conf.get("database", "SQL_ALCHEMY_CONN")

[2024-06-27T19:10:34.589+0000] {task_command.py:426} INFO - Running <TaskInstance: make_predictions.make_predictions_task manual__2024-06-27T19:10:30.429657+00:00 [running]> on host 5daea60ed64a
[2024-06-27T19:10:34.662+0000] {taskinstance.py:2648} INFO - Exporting env vars: AIRFLOW_CTX_DAG_OWNER='***' AIRFLOW_CTX_DAG_ID='make_predictions' AIRFLOW_CTX_TASK_ID='make_predictions_task' AIRFLOW_CTX_EXECUTION_DATE='2024-06-27T19:10:30.429657+00:00' AIRFLOW_CTX_TRY_NUMBER='1' AIRFLOW_CTX_DAG_RUN_ID='manual__2024-06-27T19:10:30.429657+00:00'
[2024-06-27T19:10:34.663+0000] {taskinstance.py:430} INFO - ::endgroup::
[2024-06-27T19:10:34.872+0000] {taskinstance.py:441} INFO - ::group::Post task execution logs
[2024-06-27T19:10:34.873+0000] {taskinstance.py:2905} ERROR - Task failed with exception
Traceback (most recent call last):
  File "/home/airflow/.local/lib/python3.12/site-packages/airflow/models/taskinstance.py", line 465, in _execute_task
    result = _execute_callable(context=context, **execute_callable_kwargs)
             ^^^^^^^^^^^^^^^^^^^^^^^^^^^^^^^^^^^^^^^^^^^^^^^^^^^^^^^^^^^^^
  File "/home/airflow/.local/lib/python3.12/site-packages/airflow/models/taskinstance.py", line 432, in _execute_callable
    return execute_callable(context=context, **execute_callable_kwargs)
           ^^^^^^^^^^^^^^^^^^^^^^^^^^^^^^^^^^^^^^^^^^^^^^^^^^^^^^^^^^^^
  File "/home/airflow/.local/lib/python3.12/site-packages/airflow/models/baseoperator.py", line 401, in wrapper
    return func(self, *args, **kwargs)
           ^^^^^^^^^^^^^^^^^^^^^^^^^^^
  File "/home/airflow/.local/lib/python3.12/site-packages/airflow/operators/python.py", line 235, in execute
    return_value = self.execute_callable()
                   ^^^^^^^^^^^^^^^^^^^^^^^
  File "/home/airflow/.local/lib/python3.12/site-packages/airflow/operators/python.py", line 252, in execute_callable
    return self.python_callable(*self.op_args, **self.op_kwargs)
           ^^^^^^^^^^^^^^^^^^^^^^^^^^^^^^^^^^^^^^^^^^^^^^^^^^^^^
  File "/opt/airflow/dags/make_predictions.py", line 44, in make_predictions
    model = tf.keras.models.load_model(model_path)
            ^^^^^^^^^^^^^^^^^^^^^^^^^^^^^^^^^^^^^^
  File "/home/airflow/.local/lib/python3.12/site-packages/keras/src/saving/saving_api.py", line 189, in load_model
    return legacy_h5_format.load_model_from_hdf5(
           ^^^^^^^^^^^^^^^^^^^^^^^^^^^^^^^^^^^^^^
  File "/home/airflow/.local/lib/python3.12/site-packages/keras/src/legacy/saving/legacy_h5_format.py", line 155, in load_model_from_hdf5
    **saving_utils.compile_args_from_training_config(
      ^^^^^^^^^^^^^^^^^^^^^^^^^^^^^^^^^^^^^^^^^^^^^^^
  File "/home/airflow/.local/lib/python3.12/site-packages/keras/src/legacy/saving/saving_utils.py", line 143, in compile_args_from_training_config
    loss = _deserialize_nested_config(losses.deserialize, loss_config)
           ^^^^^^^^^^^^^^^^^^^^^^^^^^^^^^^^^^^^^^^^^^^^^^^^^^^^^^^^^^^
  File "/home/airflow/.local/lib/python3.12/site-packages/keras/src/legacy/saving/saving_utils.py", line 202, in _deserialize_nested_config
    return deserialize_fn(config)
           ^^^^^^^^^^^^^^^^^^^^^^
  File "/home/airflow/.local/lib/python3.12/site-packages/keras/src/losses/__init__.py", line 149, in deserialize
    return serialization_lib.deserialize_keras_object(
           ^^^^^^^^^^^^^^^^^^^^^^^^^^^^^^^^^^^^^^^^^^^
  File "/home/airflow/.local/lib/python3.12/site-packages/keras/src/saving/serialization_lib.py", line 575, in deserialize_keras_object
    return deserialize_keras_object(
           ^^^^^^^^^^^^^^^^^^^^^^^^^
  File "/home/airflow/.local/lib/python3.12/site-packages/keras/src/saving/serialization_lib.py", line 678, in deserialize_keras_object
    return _retrieve_class_or_fn(
           ^^^^^^^^^^^^^^^^^^^^^^
  File "/home/airflow/.local/lib/python3.12/site-packages/keras/src/saving/serialization_lib.py", line 812, in _retrieve_class_or_fn
    raise TypeError(
TypeError: Could not locate function 'mse'. Make sure custom classes are decorated with `@keras.saving.register_keras_serializable()`. Full object config: {'module': 'keras.metrics', 'class_name': 'function', 'config': 'mse', 'registered_name': 'mse'}
[2024-06-27T19:10:34.891+0000] {taskinstance.py:1206} INFO - Marking task as UP_FOR_RETRY. dag_id=make_predictions, task_id=make_predictions_task, run_id=manual__2024-06-27T19:10:30.429657+00:00, execution_date=20240627T191030, start_date=20240627T191034, end_date=20240627T191034
[2024-06-27T19:10:34.900+0000] {standard_task_runner.py:110} ERROR - Failed to execute job 863 for task make_predictions_task (Could not locate function 'mse'. Make sure custom classes are decorated with `@keras.saving.register_keras_serializable()`. Full object config: {'module': 'keras.metrics', 'class_name': 'function', 'config': 'mse', 'registered_name': 'mse'}; 2467)
[2024-06-27T19:10:34.941+0000] {local_task_job_runner.py:240} INFO - Task exited with return code 1
[2024-06-27T19:10:34.954+0000] {local_task_job_runner.py:222} INFO - ::endgroup::
